Error: prefix already exists: /home/ubuntu/miniconda/envs/_pipbuild_
Requirement already satisfied (use --upgrade to upgrade): python-dateutil==2.4.2 in /home/ubuntu/miniconda/envs/_pipbuild_/lib/python2.7/site-packages
Requirement already satisfied (use --upgrade to upgrade): six>=1.5 in /home/ubuntu/miniconda/envs/_pipbuild_/lib/python2.7/site-packages (from python-dateutil==2.4.2)
Traceback (most recent call last):
  File "__tmpfile__.py", line 1, in <module>
    import pkg_resources;
ImportError: No module named pkg_resources
An unexpected error has occurred, please consider sending the
following traceback to the conda GitHub issue tracker at:

    https://github.com/conda/conda-build/issues

Include the output of the command 'conda info' in your report.


Package search: {'_pypi_ordering': False, 'version': '0.5.4', 'name': 'arrow', 'summary': 'Better dates and times for Python'}
Creating standard recipe for arrow-0.5.4
Converting recipe in /home/ubuntu/pypi-conda-builds/arrow
package = arrow
   dependencies = [u'python-dateutil']
Creating standard recipe for python-dateutil
Warning, the following versions were found for python-dateutil
2.4.2
2.4.1
2.4.0
2.3
2.2
2.1
2.0
1.5
1.4.1
1.4
1.2
1.1
1.0
0.5
0.4
0.3
0.1
Using 2.4.2
Use --version to specify a different version.
Using url https://pypi.python.org/packages/source/p/python-dateutil/python-dateutil-2.4.2.tar.gz (204 KB) for python-dateutil.
Downloading python-dateutil
Using cached download
Unpacking python-dateutil...
done
working in /tmp/tmpBf2YO8conda_skeleton_python-dateutil-2.4.2.tar.gz
Fetching package metadata: ......

WARNING: conda-build appears to be out of date. You have version 1.13.0 but the
latest version is 1.14.0. Run

conda update -n root conda-build

to get the latest version.

Solving package specifications: .patching file core.py
Hunk #1 succeeded at 168 with fuzz 2 (offset 2 lines).
Traceback (most recent call last):
  File "setup.py", line 7, in <module>
    from setuptools import setup
ImportError: No module named setuptools

Applying patch: '/tmp/tmpBf2YO8conda_skeleton_python-dateutil-2.4.2.tar.gz/pypi-distutils.patch'
$PYTHONPATH = /tmp/tmpBf2YO8conda_skeleton_python-dateutil-2.4.2.tar.gz/python-dateutil-2.4.2
Error: command failed: /home/ubuntu/miniconda/envs/_build/bin/python setup.py install

conda create -n _pipbuild_ --yes python pip
/home/ubuntu/miniconda/envs/_pipbuild_/bin/pip install python-dateutil==2.4.2
Getting dependencies...
Traceback (most recent call last):
  File "/home/ubuntu/miniconda/bin/conda-pipbuild", line 6, in <module>
    exec(compile(open(__file__).read(), __file__, 'exec'))
  File "/home/ubuntu/conda-build/bin/conda-pipbuild", line 5, in <module>
    sys.exit(main())
  File "/home/ubuntu/conda-build/conda_build/main_pipbuild.py", line 80, in main
    args_func(args, p)
  File "/home/ubuntu/conda-build/conda_build/main_build.py", line 349, in args_func
    args.func(args, p)
  File "/home/ubuntu/conda-build/conda_build/main_pipbuild.py", line 360, in execute
    build_package(package, version, noarch_python=args.noarch_python)
  File "/home/ubuntu/conda-build/conda_build/main_pipbuild.py", line 314, in build_package
    build_package(depend)
  File "/home/ubuntu/conda-build/conda_build/main_pipbuild.py", line 304, in build_package
    noarch_python=noarch_python)
  File "/home/ubuntu/conda-build/conda_build/main_pipbuild.py", line 240, in make_recipe
    depends = get_all_dependencies(package, version)
  File "/home/ubuntu/conda-build/conda_build/main_pipbuild.py", line 219, in get_all_dependencies
    output = subprocess.check_output(cmd3args)
  File "/home/ubuntu/miniconda/lib/python2.7/subprocess.py", line 573, in check_output
    raise CalledProcessError(retcode, cmd, output=output)
subprocess.CalledProcessError: Command '['/home/ubuntu/miniconda/envs/_pipbuild_/bin/python', '__tmpfile__.py']' returned non-zero exit status 1
