An unexpected error has occurred, please consider sending the
following traceback to the conda GitHub issue tracker at:

    https://github.com/conda/conda-build/issues

Include the output of the command 'conda info' in your report.


Package search: {'_pypi_ordering': False, 'version': '0.1.20150626195246', 'name': 'arvados-python-client', 'summary': 'Arvados client library'}
Creating standard recipe for arvados-python-client-0.1.20150626195246
Converting recipe in /home/ubuntu/pypi-conda-builds/arvados-python-client
package = arvados-python-client
   dependencies = [u'ciso8601', u'google-api-python-client', u'httplib2', u'pycurl >=7.19.5.1', u'python-gflags', u'ws4py']
Creating standard recipe for ciso8601
Converting recipe in /home/ubuntu/pypi-conda-builds/ciso8601
Traceback (most recent call last):
  File "/home/ubuntu/miniconda/bin/conda-pipbuild", line 6, in <module>
    exec(compile(open(__file__).read(), __file__, 'exec'))
  File "/home/ubuntu/conda-build/bin/conda-pipbuild", line 5, in <module>
    sys.exit(main())
  File "/home/ubuntu/conda-build/conda_build/main_pipbuild.py", line 80, in main
    args_func(args, p)
  File "/home/ubuntu/conda-build/conda_build/main_build.py", line 349, in args_func
    args.func(args, p)
  File "/home/ubuntu/conda-build/conda_build/main_pipbuild.py", line 360, in execute
    build_package(package, version, noarch_python=args.noarch_python)
  File "/home/ubuntu/conda-build/conda_build/main_pipbuild.py", line 314, in build_package
    build_package(depend)
  File "/home/ubuntu/conda-build/conda_build/main_pipbuild.py", line 301, in build_package
    noarch_python=noarch_python)
  File "/home/ubuntu/conda-build/conda_build/main_pipbuild.py", line 183, in convert_recipe
    d['homeurl'] = meta['about']['home']
KeyError: 'home'
