Warning, the following versions were found for plone.app.redirector
1.2.1
1.2
1.2a1
1.1.3
1.1.2
1.1.1
1.1
1.0.13
1.0.12
1.0.11
1.0.10
1.0.9
1.0.8
1.0.7
1.0.6
1.0.5
1.0.2
1.0
1.0rc1
1.0b3
1.0b2
1.0b1.1
1.0b1
1.0a2
Using 1.2.1
Use --version to specify a different version.
Using url https://pypi.python.org/packages/source/p/plone.app.redirector/plone.app.redirector-1.2.1.zip (31 KB) for plone.app.redirector.
Downloading plone.app.redirector
Using cached download
Unpacking plone.app.redirector...
done
working in /tmp/tmpLebglCconda_skeleton_plone.app.redirector-1.2.1.zip
Fetching package metadata: ......

WARNING: conda-build appears to be out of date. You have version 1.13.0 but the
latest version is 1.14.1. Run

conda update -n root conda-build

to get the latest version.

Solving package specifications: .patching file core.py
Hunk #1 succeeded at 168 with fuzz 2 (offset 2 lines).

WARNING: conda-build appears to be out of date. You have version 1.13.0 but the
latest version is 1.14.1. Run

conda update -n root conda-build

to get the latest version.


The following NEW packages will be INSTALLED:

    numpy:      1.9.2-py27_0 
    openssl:    1.0.1k-1     
    pip:        7.0.3-py27_0 
    python:     2.7.10-0     
    pyyaml:     3.11-py27_1  
    readline:   6.2-2        
    setuptools: 18.0.1-py27_0
    sqlite:     3.8.4.1-1    
    system:     5.8-2        
    tk:         8.5.18-0     
    yaml:       0.1.6-0      
    zlib:       1.2.8-0      

Linking packages ...
[                    ]|                                                  |   0%[openssl             ]|                                                  |   0%[readline            ]|####                                              |   8%[sqlite              ]|########                                          |  16%[system              ]|############                                      |  25%[tk                  ]|################                                  |  33%[yaml                ]|####################                              |  41%[zlib                ]|#########################                         |  50%[numpy               ]|#############################                     |  58%[python              ]|#################################                 |  66%[pyyaml              ]|#####################################             |  75%[setuptools          ]|#########################################         |  83%[pip                 ]|#############################################     |  91%[      COMPLETE      ]|##################################################| 100%
Applying patch: '/tmp/tmpLebglCconda_skeleton_plone.app.redirector-1.2.1.zip/pypi-distutils.patch'
Warning, the following versions were found for plone.app.contenttypes
1.2b2
1.2b1
1.2a9
1.2a8
1.2a7
1.2a6
1.2a5
1.2a4
1.2a3
1.2a2
1.2a1
1.1b5
1.1b4
1.1b3
1.1b2
1.1b1
1.1a1
1.0
1.0rc1
1.0b2
1.0b1
Using 1.2b2
Use --version to specify a different version.
Using url https://pypi.python.org/packages/source/p/plone.app.contenttypes/plone.app.contenttypes-1.2b2.tar.gz (197 KB) for plone.app.contenttypes.
Downloading plone.app.contenttypes
Using cached download
Unpacking plone.app.contenttypes...
done
working in /tmp/tmp3Zi8WCconda_skeleton_plone.app.contenttypes-1.2b2.tar.gz
Solving package specifications: .patching file core.py
Hunk #1 succeeded at 168 with fuzz 2 (offset 2 lines).

Applying patch: '/tmp/tmp3Zi8WCconda_skeleton_plone.app.contenttypes-1.2b2.tar.gz/pypi-distutils.patch'
WARNING: Could not add entry points. They were:

      # -*- Entry points: -*-
      [z3c.autoinclude.plugin]
      target = plone
      
Error: Could not parse: plone.namedfile [blobs]
