products.passwordresettool not found, trying Products.PasswordResetTool
Warning, the following versions were found for Products.PasswordResetTool
2.1.2
2.1.1
2.1.0
2.0.18
2.0.17
2.0.16
2.0.15
2.0.14
2.0.13
2.0.12
2.0.11
2.0.10
2.0.9
2.0.8
2.0.7
2.0.6
2.0.5
2.0.4
2.0.3
2.0.2
2.0.1
2.0
2.0b7
2.0b6
2.0b5
2.0b4
2.0b3
2.0b2
2.0b1
2.0a1
1.4
1.3
1.2
1.1
Using 2.1.2
Use --version to specify a different version.
Using url https://pypi.python.org/packages/source/P/Products.PasswordResetTool/Products.PasswordResetTool-2.1.2.zip (58 KB) for Products.PasswordResetTool.
Downloading Products.PasswordResetTool
Unpacking Products.PasswordResetTool...
done
working in /tmp/tmpZxCwf3conda_skeleton_Products.PasswordResetTool-2.1.2.zip
Fetching package metadata: ......

WARNING: conda-build appears to be out of date. You have version 1.13.0 but the
latest version is 1.14.1. Run

conda update -n root conda-build

to get the latest version.

Solving package specifications: .patching file core.py
Hunk #1 succeeded at 168 with fuzz 2 (offset 2 lines).

WARNING: conda-build appears to be out of date. You have version 1.13.0 but the
latest version is 1.14.1. Run

conda update -n root conda-build

to get the latest version.


Applying patch: '/tmp/tmpZxCwf3conda_skeleton_Products.PasswordResetTool-2.1.2.zip/pypi-distutils.patch'
Warning, the following versions were found for plone.app.testing
5.0b4
5.0b3
5.0b2
5.0b1
5.0a2
5.0a1
4.2.5
4.2.4
4.2.3
4.2.2
4.2.1
4.2
4.0.2
4.0.1
4.0
4.0a6
4.0a5
4.0a4
4.0a3
3.0a1
1.0a2
1.0a1
Using 5.0b4
Use --version to specify a different version.
Using url https://pypi.python.org/packages/source/p/plone.app.testing/plone.app.testing-5.0b4.tar.gz (80 KB) for plone.app.testing.
Downloading plone.app.testing
Using cached download
Unpacking plone.app.testing...
done
working in /tmp/tmp7sFDosconda_skeleton_plone.app.testing-5.0b4.tar.gz
Solving package specifications: .patching file core.py
Hunk #1 succeeded at 168 with fuzz 2 (offset 2 lines).

Applying patch: '/tmp/tmp7sFDosconda_skeleton_plone.app.testing-5.0b4.tar.gz/pypi-distutils.patch'
Error: Could not parse: plone.testing [zca,security,zodb,z2]
