Warning, the following versions were found for slpkg
2.5.8
2.5.7
2.5.6
2.5.5
2.5.4
2.5.3
2.5.2
2.5.1
2.5.0
2.4.4
2.4.3
2.4.2
2.4.1
2.4.0
2.3.6
2.3.5
2.3.4
2.3.3
2.3.2
2.3.1
2.3.0
2.2.9
2.2.8
2.2.7
2.2.6
2.2.5
2.2.3
2.2.2
2.2.1
2.2.0
2.1.5
2.1.4
2.1.3
2.1.2
2.1.1
2.1.0
2.0.9
2.0.8
2.0.7
2.0.6
2.0.5
2.0.4
2.0.3
2.0.2
2.0.1
2.0.0
1.9.9
1.9.8
1.9.7
1.9.6
1.9.5
1.9.4
1.9.3
1.9.2
1.9.1
1.9.0
1.8.9
1.8.8
1.8.7
1.8.6
1.8.5
1.8.4
1.8.3
1.8.2
1.8.1
1.8.0
1.7.9
1.7.8
1.7.7
1.7.6
1.7.5
1.7.4
1.7.3
1.7.2
1.7.1
1.7.0
1.6.9
1.6.8
1.6.7
1.6.6
1.6.5
1.6.4
1.6.3
1.6.2
1.6.1
1.6.0
1.5.9
1.5.8
1.5.7
1.5.6
1.5.5
1.5.4
1.5.3
1.5.2
1.5.1
1.5.0
1.4.9
1.4.8
1.4.7
1.4.6
1.4.5
1.4.4
1.4.3
1.4.2
1.4.1
1.4.0
1.3.9
1.3.8
1.3.7
1.3.6
1.3.5
1.3.4
1.3.3
1.3.2
1.3.1
1.3.0
1.2.9
1.2.8
1.2.7
1.2.6
1.2.5
1.2.4
1.2.3
1.2.2
1.2.1
1.2.0
1.1.9
1.1.8
1.1.7
1.1.6
1.1.5
1.1.4
1.1.3
1.1.2
1.1.1
1.1.0
1.0.9
1.0.8
1.0.7
1.0.6
1.0.5
1.0.3
(latest release)
Using 2.5.8
Use --version to specify a different version.
Using url https://pypi.python.org/packages/source/s/slpkg/slpkg-2.5.8.tar.gz (94 KB) for slpkg.
Downloading slpkg
Unpacking slpkg...
done
working in /tmp/tmpJLJccCconda_skeleton_slpkg-2.5.8.tar.gz
Fetching package metadata: ......

WARNING: conda-build appears to be out of date. You have version 1.13.0 but the
latest version is 1.14.1. Run

conda update -n root conda-build

to get the latest version.

Solving package specifications: .patching file core.py
Hunk #1 succeeded at 168 with fuzz 2 (offset 2 lines).

slpkg: error: must have root privileges

An unexpected error has occurred, please consider sending the
following traceback to the conda GitHub issue tracker at:

    https://github.com/conda/conda-build/issues

Include the output of the command 'conda info' in your report.



The following NEW packages will be INSTALLED:

    numpy:  1.9.2-py27_0
    pyyaml: 3.11-py27_1 
    yaml:   0.1.6-0     

Linking packages ...
[                    ]|                                                  |   0%[yaml                ]|                                                  |   0%[numpy               ]|################                                  |  33%[pyyaml              ]|#################################                 |  66%[      COMPLETE      ]|##################################################| 100%
Applying patch: '/tmp/tmpJLJccCconda_skeleton_slpkg-2.5.8.tar.gz/pypi-distutils.patch'
Traceback (most recent call last):
  File "/home/ubuntu/miniconda/bin/conda-skeleton", line 6, in <module>
    exec(compile(open(__file__).read(), __file__, 'exec'))
  File "/home/ubuntu/conda-build/bin/conda-skeleton", line 5, in <module>
    sys.exit(main())
  File "/home/ubuntu/conda-build/conda_build/main_skeleton.py", line 240, in main
    args_func(args, p)
  File "/home/ubuntu/conda-build/conda_build/main_build.py", line 349, in args_func
    args.func(args, p)
  File "/home/ubuntu/conda-build/conda_build/main_skeleton.py", line 254, in execute
    pypi.main(args, parser)
  File "/home/ubuntu/conda-build/conda_build/pypi.py", line 387, in main
    get_package_metadata(args, package, d, data)
  File "/home/ubuntu/conda-build/conda_build/pypi.py", line 485, in get_package_metadata
    with open(join(tempdir, 'pkginfo.yaml')) as fn:
IOError: [Errno 2] No such file or directory: '/tmp/tmpJLJccCconda_skeleton_slpkg-2.5.8.tar.gz/pkginfo.yaml'
